<?xml version="1.0" ?>

<robot name="dot" xmlns:xacro="https://www.ros.org/wiki/xacro" >

  <xacro:property name="scale" default="0.5" />
  <xacro:property name="camera_link" value="0.05" /> <!-- Size of square 'camera' box -->

  <gazebo>
    <plugin name="gazebo_ros_control" filename="libgazebo_ros_control.so">
      <robotNamespace>/dot</robotNamespace>
    </plugin>
  </gazebo>    
    
  <material name="black">
    <color rgba="0.0 0.0 0.0 1.0"/>
  </material>
  <material name="blue">
    <color rgba="0.203125 0.23828125 0.28515625 1.0"/>
  </material>
  <material name="green">
    <color rgba="0.0 0.8 0.0 1.0"/>
  </material>
  <material name="grey">
    <color rgba="0.2 0.2 0.2 1.0"/>
  </material>
  <material name="orange">
    <color rgba="1.0 0.423529411765 0.0392156862745 1.0"/>
  </material>
  <material name="brown">
    <color rgba="0.870588235294 0.811764705882 0.764705882353 1.0"/>
  </material>
  <material name="red">
    <color rgba="0.796078431 0.262745098 0.207843137 1.0"/>
  </material>
  <material name="white">
    <color rgba="1.0 1.0 1.0 1.0"/>
  </material>  
  
  <!-- <gazebo reference="link_chassis">
    <material>Gazebo/Red</material>
  </gazebo> --> 
  <gazebo reference="caster_link">
    <material>Gazebo/Black</material>
  </gazebo> 
  <gazebo reference="link_left_wheel">
    <material>Gazebo/Black</material>
  </gazebo>
  <gazebo reference="link_right_wheel">
    <material>Gazebo/Black</material>
  </gazebo>
    
  <link name="link_chassis">
    <!-- pose and inertial -->
    <pose>0 0 0.1 0 0 0</pose>
    
    <inertial>
      <mass value="${5 * scale}"/>
      <origin rpy="0 0 0" xyz="0 0 0"/>
      <inertia ixx="0.0395416666667" ixy="0" ixz="0" iyy="0.106208333333" iyz="0" izz="0.106208333333"/>
    </inertial>
    
    <collision name="collision_chassis">
      <geometry>
        <cylinder length="${0.07 * scale}" radius="${0.3 * scale}"/>
      </geometry>
    </collision>
    
    <visual>
      <origin rpy="0 0 0" xyz="0 0 0"/>
      <geometry>
        <cylinder length="${0.07 * scale}" radius="${0.3 * scale}"/>
      </geometry>
      <material name="red"/>
    </visual>
    </link> 

  <!-- caster front -->
  <link name="caster_link_1">
    <inertial>
      <mass value="${0.2 * scale}"/>
      <origin rpy="0 0 0" xyz="0 0 0"/>
      <inertia ixx="0.00052666666" ixy="0" ixz="0" iyy="0.00052666666" iyz="0" izz="0.001"/>
    </inertial>
    <collision>
      <origin rpy="0 0 0" xyz="0 0 0" />
      <geometry>
        <sphere radius="${0.033 * scale}"/>
      </geometry>
    </collision>
    <visual>
      <origin rpy="0 0 0" xyz="0 0 0"/>
      <geometry>
        <sphere radius="${0.033 * scale}"/>
      </geometry>
    </visual>
  </link>

  <link name="dummy_link_1">
    <inertial>
      <mass value="${0.001 * scale}"/>
      <origin rpy="0 0 0" xyz="0 0 0"/>
      <inertia ixx="0" ixy="0" ixz="0" iyy="0.0" iyz="0" izz="0"/>
    </inertial>
  </link>

  <joint name="caster_joint_11" type="revolute">
    <origin rpy="0 0 0" xyz="${0.2 * scale} ${0 * scale} ${-0.0675 * scale}" />
    <child link="dummy_link_1" />
    <parent link="link_chassis" />
    <axis xyz="0 0 1" />
    <limit effort="0.26" velocity="20" />
    <joint_properties damping="0.1" friction="0.2" />
  </joint>

  <joint name="caster_joint_12" type="revolute">
    <origin rpy="0 0 0" xyz="0 0 0"/>
    <child link="caster_link_1" />
    <parent link="dummy_link_1" />
    <axis xyz="0 1 0" />
    <limit effort="0.26" velocity="20" />
    <joint_properties damping="0.1" friction="0.2" />
  </joint>

  <link name="caster_link_2">
    <inertial>
      <mass value="${0.2 * scale}"/>
      <origin rpy="0 0 0" xyz="0 0 0"/>
      <inertia ixx="0.00052666666" ixy="0" ixz="0" iyy="0.00052666666" iyz="0" izz="0.001"/>
    </inertial>
    <collision>
      <origin rpy="0 0 0" xyz="0 0 0" />
      <geometry>
        <sphere radius="${0.033 * scale}"/>
      </geometry>
    </collision>
    <visual>
      <origin rpy="0 0 0" xyz="0 0 0"/>
      <geometry>
        <sphere radius="${0.033 * scale}"/>
      </geometry>
    </visual>
  </link>

  <link name="dummy_link_2">
    <inertial>
      <mass value="${0.001 * scale}"/>
      <origin rpy="0 0 0" xyz="0 0 0"/>
      <inertia ixx="0" ixy="0" ixz="0" iyy="0.0" iyz="0" izz="0"/>
    </inertial>
  </link>

  <joint name="caster_joint_21" type="revolute">
    <origin rpy="0 0 0" xyz="${-0.2 * scale} ${0 * scale} ${-0.0675 * scale}"/>
    <child link="dummy_link_2" />
    <parent link="link_chassis" />
    <axis xyz="0 0 1" />
    <limit effort="0.26" velocity="20" />
    <joint_properties damping="0.1" friction="0.2" />
  </joint>

  <joint name="caster_joint_22" type="revolute">
    <origin rpy="0 0 0" xyz="0 0 0"/>
    <child link="caster_link_2" />
    <parent link="dummy_link_2" />
    <axis xyz="0 1 0" />
    <limit effort="0.26" velocity="20" />
    <joint_properties damping="0.1" friction="0.2" />
  </joint>
  
  <!-- Create wheel right -->  
    
  <link name="link_right_wheel">    
    <inertial>
      <mass value="${0.2 * scale}"/>
      <origin rpy="0 1.5707 1.5707" xyz="0 0 0"/>
      <inertia ixx="0.00052666666" ixy="0" ixz="0" iyy="0.00052666666" iyz="0" izz="0.001"/>
    </inertial>
    
    <collision name="link_right_wheel_collision">
      <origin rpy="0 1.5707 1.5707" xyz="0 0 0" />
      <geometry>
        <cylinder length="${0.04 * scale}" radius="${0.1 * scale}"/>
      </geometry>
    </collision>
    
    <visual name="link_right_wheel_visual">
      <origin rpy="0 1.5707 1.5707" xyz="0 0 0"/>
      <geometry>
        <cylinder length="${0.04 * scale}" radius="${0.1 * scale}"/>
      </geometry>      
    </visual>
    
  </link>
    
  <!--   Joint for right wheel  -->
  <joint name="joint_right_wheel" type="continuous">
    <origin rpy="0 0 0" xyz="${0 * scale} ${0.33 * scale} ${0 * scale}"/>
    <child link="link_right_wheel" />
    <parent link="link_chassis"/>
    <axis rpy="0 0 0" xyz="${0 * scale} ${1 * scale} ${0 * scale}"/>
    <limit effort="2.6" velocity="20"/>
    <joint_properties damping="0.1" friction="0.2" />
  </joint>  
    
  <!-- Left Wheel link -->
    
  <link name="link_left_wheel">    
    <inertial>
      <mass value="${0.2 * scale}"/>
      <origin rpy="0 1.5707 1.5707" xyz="0 0 0"/>
      <inertia ixx="0.00052666666" ixy="0" ixz="0" iyy="0.00052666666" iyz="0" izz="0.001"/>
    </inertial>
    
    <collision name="link_left_wheel_collision">
      <origin rpy="0 1.5707 1.5707" xyz="0 0 0" />
      <geometry>
        <cylinder length="${0.04 * scale}" radius="${0.1 * scale}"/>
      </geometry>
    </collision>
    
    <visual name="link_left_wheel_visual">
      <origin rpy="0 1.5707 1.5707" xyz="0 0 0"/>
      <geometry>
        <cylinder length="${0.04 * scale}" radius="${0.1 * scale}"/>
      </geometry>      
    </visual>
    
  </link>
    
  <!--   Joint for left wheel  -->
  <joint name="joint_left_wheel" type="continuous">
    <origin rpy="0 0 0" xyz="${0 * scale} ${-0.33 * scale} ${0 * scale}"/>
    <child link="link_left_wheel" />
    <parent link="link_chassis"/>
    <axis rpy="0 0 0" xyz="0 1 0"/>
    <limit effort="2.6" velocity="20"/>
    <joint_properties damping="0.1" friction="0.2" />
  </joint>    

  <transmission name="tran1">
    <type>transmission_interface/SimpleTransmission</type>
    <joint name="joint_right_wheel">
      <hardwareInterface>hardware_interface/EffortJointInterface</hardwareInterface>
    </joint>
    <actuator name="right_motor">
      <hardwareInterface>hardware_interface/EffortJointInterface</hardwareInterface>
      <mechanicalReduction>50</mechanicalReduction>
    </actuator>
  </transmission>

  <transmission name="tran2">
    <type>transmission_interface/SimpleTransmission</type>
    <joint name="joint_left_wheel">
      <hardwareInterface>hardware_interface/EffortJointInterface</hardwareInterface>
    </joint>
    <actuator name="left_motor">
      <hardwareInterface>hardware_interface/EffortJointInterface</hardwareInterface>
      <mechanicalReduction>50</mechanicalReduction>
    </actuator>
  </transmission>

  <!-- Block Laser -->
  <joint name="hokuyo_joint" type="fixed">
    <axis xyz="0 1 0" />
    <origin xyz="${camera_link} 0 ${0.07 * scale}" rpy="0 0 0"/>
    <parent link="link_chassis"/>
    <child link="hokuyo_link"/>
  </joint>

  <!-- Hokuyo Laser -->
  <link name="hokuyo_link">
    <collision>
      <origin xyz="0 0 0" rpy="0 0 0"/>
      <geometry>
    <box size="0.1 0.1 0.1"/>
      </geometry>
    </collision>

    <visual>
      <origin xyz="0 0 0" rpy="0 0 0"/>
      <geometry>
        <box size="${camera_link} ${camera_link} ${camera_link}"/>
      </geometry>
    </visual>

    <inertial>
      <mass value="1e-5" />
      <origin xyz="0 0 0" rpy="0 0 0"/>
      <inertia ixx="1e-6" ixy="0" ixz="0" iyy="1e-6" iyz="0" izz="1e-6" />
    </inertial>
  </link>
  
  <!-- hokuyo -->
  <gazebo reference="hokuyo_link">
    <sensor type="gpu_ray" name="head_hokuyo_sensor">
      <pose>0 0 0 0 0 0</pose>
      <visualize>true</visualize>
      <update_rate>40</update_rate>
      <ray>
        <scan>
          <horizontal>
            <samples>720</samples>
            <resolution>1</resolution>
            <min_angle>-1.570796</min_angle>
            <max_angle>1.570796</max_angle>
          </horizontal>
        </scan>
        <range>
          <min>0.10</min>
          <max>30.0</max>
          <resolution>0.01</resolution>
        </range>
        <noise>
          <type>gaussian</type>
          <!-- Noise parameters based on published spec for Hokuyo laser
               achieving "+-30mm" accuracy at range < 10m.  A mean of 0.0m and
               stddev of 0.01m will put 99.7% of samples within 0.03m of the true
               reading. -->
          <mean>0.0</mean>
          <stddev>0.01</stddev>
        </noise>
      </ray>
      <plugin name="gazebo_ros_head_hokuyo_controller" filename="libgazebo_ros_gpu_laser.so">
        <topicName>/dot/laser/scan</topicName>
        <frameName>hokuyo_link</frameName>
      </plugin>
    </sensor>
  </gazebo>
  
</robot>
